2021-08-19 18:17:52,970 ERROR: Exception on /login [GET] [in c:\code\personal\microblog\venv\lib\site-packages\flask\app.py:1454]
Traceback (most recent call last):
  File "c:\code\personal\microblog\venv\lib\site-packages\flask\app.py", line 2070, in wsgi_app
    response = self.full_dispatch_request()
  File "c:\code\personal\microblog\venv\lib\site-packages\flask\app.py", line 1515, in full_dispatch_request
    rv = self.handle_user_exception(e)
  File "c:\code\personal\microblog\venv\lib\site-packages\flask\app.py", line 1513, in full_dispatch_request
    rv = self.dispatch_request()
  File "c:\code\personal\microblog\venv\lib\site-packages\flask\app.py", line 1499, in dispatch_request
    return self.ensure_sync(self.view_functions[rule.endpoint])(**req.view_args)
  File "C:\Code\Personal\microblog\app\routes.py", line 29, in login
    return render_template('login.html', title='Sign In', form=form)
  File "c:\code\personal\microblog\venv\lib\site-packages\flask\templating.py", line 147, in render_template
    return _render(
  File "c:\code\personal\microblog\venv\lib\site-packages\flask\templating.py", line 128, in _render
    rv = template.render(context)
  File "c:\code\personal\microblog\venv\lib\site-packages\jinja2\environment.py", line 1304, in render
    self.environment.handle_exception()
  File "c:\code\personal\microblog\venv\lib\site-packages\jinja2\environment.py", line 925, in handle_exception
    raise rewrite_traceback_stack(source=source)
  File "C:\Code\Personal\microblog\app\templates\login.html", line 1, in top-level template code
    {% extends 'base.html' %}
  File "c:\code\personal\microblog\venv\lib\site-packages\jinja2\environment.py", line 925, in handle_exception
    raise rewrite_traceback_stack(source=source)
  File "C:\Code\Personal\microblog\app\templates\base.html", line 96, in template
    {% end block %}
jinja2.exceptions.TemplateSyntaxError: Encountered unknown tag 'end'. Jinja was looking for the following tags: 'endblock'. The innermost block that needs to be closed is 'block'.
2021-08-19 18:18:01,761 ERROR: Exception on /favicon.ico [GET] [in c:\code\personal\microblog\venv\lib\site-packages\flask\app.py:1454]
Traceback (most recent call last):
  File "c:\code\personal\microblog\venv\lib\site-packages\flask\app.py", line 1513, in full_dispatch_request
    rv = self.dispatch_request()
  File "c:\code\personal\microblog\venv\lib\site-packages\flask\app.py", line 1489, in dispatch_request
    self.raise_routing_exception(req)
  File "c:\code\personal\microblog\venv\lib\site-packages\flask\app.py", line 1471, in raise_routing_exception
    raise request.routing_exception  # type: ignore
  File "c:\code\personal\microblog\venv\lib\site-packages\flask\ctx.py", line 367, in match_request
    result = self.url_adapter.match(return_rule=True)  # type: ignore
  File "c:\code\personal\microblog\venv\lib\site-packages\werkzeug\routing.py", line 2032, in match
    raise NotFound()
werkzeug.exceptions.NotFound: 404 Not Found: The requested URL was not found on the server. If you entered the URL manually please check your spelling and try again.

During handling of the above exception, another exception occurred:

Traceback (most recent call last):
  File "c:\code\personal\microblog\venv\lib\site-packages\flask\app.py", line 2070, in wsgi_app
    response = self.full_dispatch_request()
  File "c:\code\personal\microblog\venv\lib\site-packages\flask\app.py", line 1515, in full_dispatch_request
    rv = self.handle_user_exception(e)
  File "c:\code\personal\microblog\venv\lib\site-packages\flask\app.py", line 1383, in handle_user_exception
    return self.handle_http_exception(e)
  File "c:\code\personal\microblog\venv\lib\site-packages\flask\app.py", line 1323, in handle_http_exception
    return self.ensure_sync(handler)(e)
  File "C:\Code\Personal\microblog\app\errors.py", line 6, in not_found_error
    return render_template('404.html'), 404
  File "c:\code\personal\microblog\venv\lib\site-packages\flask\templating.py", line 147, in render_template
    return _render(
  File "c:\code\personal\microblog\venv\lib\site-packages\flask\templating.py", line 128, in _render
    rv = template.render(context)
  File "c:\code\personal\microblog\venv\lib\site-packages\jinja2\environment.py", line 1304, in render
    self.environment.handle_exception()
  File "c:\code\personal\microblog\venv\lib\site-packages\jinja2\environment.py", line 925, in handle_exception
    raise rewrite_traceback_stack(source=source)
  File "C:\Code\Personal\microblog\app\templates\404.html", line 1, in top-level template code
    {% extends "base.html" %}
  File "c:\code\personal\microblog\venv\lib\site-packages\jinja2\environment.py", line 925, in handle_exception
    raise rewrite_traceback_stack(source=source)
  File "C:\Code\Personal\microblog\app\templates\base.html", line 96, in template
    {% end block %}
jinja2.exceptions.TemplateSyntaxError: Encountered unknown tag 'end'. Jinja was looking for the following tags: 'endblock'. The innermost block that needs to be closed is 'block'.
2021-08-19 18:18:17,183 INFO: Microblog startup [in C:\Code\Personal\microblog\app\__init__.py:52]
2021-08-19 18:19:24,635 ERROR: Exception on /explore [GET] [in c:\code\personal\microblog\venv\lib\site-packages\flask\app.py:1454]
Traceback (most recent call last):
  File "c:\code\personal\microblog\venv\lib\site-packages\flask\app.py", line 2070, in wsgi_app
    response = self.full_dispatch_request()
  File "c:\code\personal\microblog\venv\lib\site-packages\flask\app.py", line 1515, in full_dispatch_request
    rv = self.handle_user_exception(e)
  File "c:\code\personal\microblog\venv\lib\site-packages\flask\app.py", line 1513, in full_dispatch_request
    rv = self.dispatch_request()
  File "c:\code\personal\microblog\venv\lib\site-packages\flask\app.py", line 1499, in dispatch_request
    return self.ensure_sync(self.view_functions[rule.endpoint])(**req.view_args)
  File "c:\code\personal\microblog\venv\lib\site-packages\flask_login\utils.py", line 272, in decorated_view
    return func(*args, **kwargs)
  File "C:\Code\Personal\microblog\app\routes.py", line 165, in explore
    return render_template("index.html", title='Explore', posts=posts.items,
  File "c:\code\personal\microblog\venv\lib\site-packages\flask\templating.py", line 147, in render_template
    return _render(
  File "c:\code\personal\microblog\venv\lib\site-packages\flask\templating.py", line 128, in _render
    rv = template.render(context)
  File "c:\code\personal\microblog\venv\lib\site-packages\jinja2\environment.py", line 1304, in render
    self.environment.handle_exception()
  File "c:\code\personal\microblog\venv\lib\site-packages\jinja2\environment.py", line 925, in handle_exception
    raise rewrite_traceback_stack(source=source)
  File "C:\Code\Personal\microblog\app\templates\index.html", line 2, in top-level template code
    {% import 'bootstrap/wtf.html' as wtf %}
  File "C:\Code\Personal\microblog\app\templates\base.html", line 1, in top-level template code
    {% extends 'bootstrap/base.html' %}
  File "c:\code\personal\microblog\venv\lib\site-packages\flask_bootstrap\templates\bootstrap\base.html", line 1, in top-level template code
    {% block doc -%}
  File "c:\code\personal\microblog\venv\lib\site-packages\flask_bootstrap\templates\bootstrap\base.html", line 4, in block 'doc'
    {%- block html %}
  File "c:\code\personal\microblog\venv\lib\site-packages\flask_bootstrap\templates\bootstrap\base.html", line 20, in block 'html'
    {% block body -%}
  File "c:\code\personal\microblog\venv\lib\site-packages\flask_bootstrap\templates\bootstrap\base.html", line 23, in block 'body'
    {% block content -%}
  File "C:\Code\Personal\microblog\app\templates\base.html", line 87, in block 'content'
    {% block app_content %}{% endblock %}
  File "C:\Code\Personal\microblog\app\templates\index.html", line 11, in block 'app_content'
    {% include '_post.html' %}
  File "C:\Code\Personal\microblog\app\templates\_post.html", line 12, in top-level template code
    said {{ momoent(post.timestamp).fromNow() }}:
  File "c:\code\personal\microblog\venv\lib\site-packages\jinja2\utils.py", line 84, in from_obj
    if hasattr(obj, "jinja_pass_arg"):
jinja2.exceptions.UndefinedError: 'momoent' is undefined
