2020-11-03 16:52:13,187 ERROR: Exception on /reset_password_request [POST] [in c:\users\xuse\desktop\microblog\venv\lib\site-packages\flask\app.py:1891]
Traceback (most recent call last):
  File "c:\users\xuse\desktop\microblog\venv\lib\site-packages\flask_mail.py", line 492, in send
    message.send(connection)
  File "c:\users\xuse\desktop\microblog\venv\lib\site-packages\flask_mail.py", line 427, in send
    connection.send(self)
  File "c:\users\xuse\desktop\microblog\venv\lib\site-packages\flask_mail.py", line 188, in send
    self.host.sendmail(sanitize_address(envelope_from or message.sender),
  File "C:\Users\xuse\AppData\Local\Programs\Python\Python38-32\lib\smtplib.py", line 856, in sendmail
    self.ehlo_or_helo_if_needed()
  File "C:\Users\xuse\AppData\Local\Programs\Python\Python38-32\lib\smtplib.py", line 604, in ehlo_or_helo_if_needed
    if not (200 <= self.ehlo()[0] <= 299):
  File "C:\Users\xuse\AppData\Local\Programs\Python\Python38-32\lib\smtplib.py", line 444, in ehlo
    self.putcmd(self.ehlo_msg, name or self.local_hostname)
  File "C:\Users\xuse\AppData\Local\Programs\Python\Python38-32\lib\smtplib.py", line 371, in putcmd
    self.send(str)
  File "C:\Users\xuse\AppData\Local\Programs\Python\Python38-32\lib\smtplib.py", line 363, in send
    raise SMTPServerDisconnected('please run connect() first')
smtplib.SMTPServerDisconnected: please run connect() first

During handling of the above exception, another exception occurred:

Traceback (most recent call last):
  File "c:\users\xuse\desktop\microblog\venv\lib\site-packages\flask\app.py", line 2447, in wsgi_app
    response = self.full_dispatch_request()
  File "c:\users\xuse\desktop\microblog\venv\lib\site-packages\flask\app.py", line 1952, in full_dispatch_request
    rv = self.handle_user_exception(e)
  File "c:\users\xuse\desktop\microblog\venv\lib\site-packages\flask\app.py", line 1821, in handle_user_exception
    reraise(exc_type, exc_value, tb)
  File "c:\users\xuse\desktop\microblog\venv\lib\site-packages\flask\_compat.py", line 39, in reraise
    raise value
  File "c:\users\xuse\desktop\microblog\venv\lib\site-packages\flask\app.py", line 1950, in full_dispatch_request
    rv = self.dispatch_request()
  File "c:\users\xuse\desktop\microblog\venv\lib\site-packages\flask\app.py", line 1936, in dispatch_request
    return self.view_functions[rule.endpoint](**req.view_args)
  File "C:\Users\xuse\Desktop\microblog\app\routes.py", line 179, in reset_password_request
    send_password_reset_email(user)
  File "C:\Users\xuse\Desktop\microblog\app\email.py", line 15, in send_password_reset_email
    send_email('[Microblog] Reset Your Password',
  File "C:\Users\xuse\Desktop\microblog\app\email.py", line 10, in send_email
    mail.send(msg)
  File "c:\users\xuse\desktop\microblog\venv\lib\site-packages\flask_mail.py", line 492, in send
    message.send(connection)
  File "c:\users\xuse\desktop\microblog\venv\lib\site-packages\flask_mail.py", line 152, in __exit__
    self.host.quit()
  File "C:\Users\xuse\AppData\Local\Programs\Python\Python38-32\lib\smtplib.py", line 988, in quit
    res = self.docmd("quit")
  File "C:\Users\xuse\AppData\Local\Programs\Python\Python38-32\lib\smtplib.py", line 424, in docmd
    self.putcmd(cmd, args)
  File "C:\Users\xuse\AppData\Local\Programs\Python\Python38-32\lib\smtplib.py", line 371, in putcmd
    self.send(str)
  File "C:\Users\xuse\AppData\Local\Programs\Python\Python38-32\lib\smtplib.py", line 363, in send
    raise SMTPServerDisconnected('please run connect() first')
smtplib.SMTPServerDisconnected: please run connect() first
2020-11-03 16:53:03,370 INFO: Microblog startup [in C:\Users\xuse\Desktop\microblog\app\__init__.py:45]
2020-11-03 16:57:00,747 INFO: Microblog startup [in C:\Users\xuse\Desktop\microblog\app\__init__.py:45]
2020-11-03 17:00:37,176 INFO: Microblog startup [in C:\Users\xuse\Desktop\microblog\app\__init__.py:45]
2020-11-03 17:05:06,644 INFO: Microblog startup [in C:\Users\xuse\Desktop\microblog\app\__init__.py:45]
2020-11-03 17:05:31,095 ERROR: Exception on /reset_password_request [POST] [in c:\users\xuse\desktop\microblog\venv\lib\site-packages\flask\app.py:1891]
Traceback (most recent call last):
  File "c:\users\xuse\desktop\microblog\venv\lib\site-packages\flask\app.py", line 2447, in wsgi_app
    response = self.full_dispatch_request()
  File "c:\users\xuse\desktop\microblog\venv\lib\site-packages\flask\app.py", line 1952, in full_dispatch_request
    rv = self.handle_user_exception(e)
  File "c:\users\xuse\desktop\microblog\venv\lib\site-packages\flask\app.py", line 1821, in handle_user_exception
    reraise(exc_type, exc_value, tb)
  File "c:\users\xuse\desktop\microblog\venv\lib\site-packages\flask\_compat.py", line 39, in reraise
    raise value
  File "c:\users\xuse\desktop\microblog\venv\lib\site-packages\flask\app.py", line 1950, in full_dispatch_request
    rv = self.dispatch_request()
  File "c:\users\xuse\desktop\microblog\venv\lib\site-packages\flask\app.py", line 1936, in dispatch_request
    return self.view_functions[rule.endpoint](**req.view_args)
  File "C:\Users\xuse\Desktop\microblog\app\routes.py", line 179, in reset_password_request
    send_password_reset_email(user)
  File "C:\Users\xuse\Desktop\microblog\app\email.py", line 17, in send_password_reset_email
    recipients=[user.email, ['ADMINS'][1]],
IndexError: list index out of range
2020-11-03 17:06:41,909 INFO: Microblog startup [in C:\Users\xuse\Desktop\microblog\app\__init__.py:45]
2020-11-03 17:08:04,140 ERROR: Exception on /reset_password/eyJ0eXAiOiJKV1QiLCJhbGciOiJIUzI1NiJ9.eyJyZXNldF9wYXNzd29yZCI6OCwiZXhwIjoxNjA0NDQ4NjQ5LjU1NzkyNDd9.zsV5U0FBRCvPvEiHooFKq6D9Pd4-0-FhKQ6Bxn9Wzl4 [GET] [in c:\users\xuse\desktop\microblog\venv\lib\site-packages\flask\app.py:1891]
Traceback (most recent call last):
  File "c:\users\xuse\desktop\microblog\venv\lib\site-packages\flask\app.py", line 2447, in wsgi_app
    response = self.full_dispatch_request()
  File "c:\users\xuse\desktop\microblog\venv\lib\site-packages\flask\app.py", line 1952, in full_dispatch_request
    rv = self.handle_user_exception(e)
  File "c:\users\xuse\desktop\microblog\venv\lib\site-packages\flask\app.py", line 1821, in handle_user_exception
    reraise(exc_type, exc_value, tb)
  File "c:\users\xuse\desktop\microblog\venv\lib\site-packages\flask\_compat.py", line 39, in reraise
    raise value
  File "c:\users\xuse\desktop\microblog\venv\lib\site-packages\flask\app.py", line 1950, in full_dispatch_request
    rv = self.dispatch_request()
  File "c:\users\xuse\desktop\microblog\venv\lib\site-packages\flask\app.py", line 1936, in dispatch_request
    return self.view_functions[rule.endpoint](**req.view_args)
  File "C:\Users\xuse\Desktop\microblog\app\routes.py", line 188, in reset_password
    if current_user.is_authenitcated:
  File "c:\users\xuse\desktop\microblog\venv\lib\site-packages\werkzeug\local.py", line 347, in __getattr__
    return getattr(self._get_current_object(), name)
AttributeError: 'AnonymousUserMixin' object has no attribute 'is_authenitcated'
2020-11-03 17:09:38,879 INFO: Microblog startup [in C:\Users\xuse\Desktop\microblog\app\__init__.py:45]
2020-11-03 17:13:31,406 INFO: Microblog startup [in C:\Users\xuse\Desktop\microblog\app\__init__.py:45]
2020-11-03 17:15:26,079 INFO: Microblog startup [in C:\Users\xuse\Desktop\microblog\app\__init__.py:45]
2020-11-04 16:35:29,950 INFO: Microblog startup [in C:\Users\xuse\Desktop\microblog\app\__init__.py:49]
