2021-09-09 21:44:32,786 ERROR: Exception on /explore [GET] [in c:\code\personal\microblog\venv\lib\site-packages\flask\app.py:1454]
Traceback (most recent call last):
  File "c:\code\personal\microblog\venv\lib\site-packages\flask\app.py", line 2070, in wsgi_app
    response = self.full_dispatch_request()
  File "c:\code\personal\microblog\venv\lib\site-packages\flask\app.py", line 1515, in full_dispatch_request
    rv = self.handle_user_exception(e)
  File "c:\code\personal\microblog\venv\lib\site-packages\flask\app.py", line 1513, in full_dispatch_request
    rv = self.dispatch_request()
  File "c:\code\personal\microblog\venv\lib\site-packages\flask\app.py", line 1499, in dispatch_request
    return self.ensure_sync(self.view_functions[rule.endpoint])(**req.view_args)
  File "c:\code\personal\microblog\venv\lib\site-packages\flask_login\utils.py", line 272, in decorated_view
    return func(*args, **kwargs)
  File "C:\Code\Personal\microblog\app\routes.py", line 62, in explore
    return render_template('index.html', title=_('Explore'),
  File "c:\code\personal\microblog\venv\lib\site-packages\flask\templating.py", line 147, in render_template
    return _render(
  File "c:\code\personal\microblog\venv\lib\site-packages\flask\templating.py", line 128, in _render
    rv = template.render(context)
  File "c:\code\personal\microblog\venv\lib\site-packages\jinja2\environment.py", line 1304, in render
    self.environment.handle_exception()
  File "c:\code\personal\microblog\venv\lib\site-packages\jinja2\environment.py", line 925, in handle_exception
    raise rewrite_traceback_stack(source=source)
  File "C:\Code\Personal\microblog\app\templates\index.html", line 1, in top-level template code
    {% extends "base.html" %}
  File "c:\code\personal\microblog\venv\lib\site-packages\jinja2\environment.py", line 925, in handle_exception
    raise rewrite_traceback_stack(source=source)
  File "C:\Code\Personal\microblog\app\templates\base.html", line 99, in template
    $(destElem).html('<img src="{{ url_for(\'static\', filename=\'loading.gif\') }}">');
jinja2.exceptions.TemplateSyntaxError: unexpected char '\\' at 3559
2021-09-09 21:44:38,715 ERROR: Exception on /favicon.ico [GET] [in c:\code\personal\microblog\venv\lib\site-packages\flask\app.py:1454]
Traceback (most recent call last):
  File "c:\code\personal\microblog\venv\lib\site-packages\flask\app.py", line 1513, in full_dispatch_request
    rv = self.dispatch_request()
  File "c:\code\personal\microblog\venv\lib\site-packages\flask\app.py", line 1489, in dispatch_request
    self.raise_routing_exception(req)
  File "c:\code\personal\microblog\venv\lib\site-packages\flask\app.py", line 1471, in raise_routing_exception
    raise request.routing_exception  # type: ignore
  File "c:\code\personal\microblog\venv\lib\site-packages\flask\ctx.py", line 367, in match_request
    result = self.url_adapter.match(return_rule=True)  # type: ignore
  File "c:\code\personal\microblog\venv\lib\site-packages\werkzeug\routing.py", line 2032, in match
    raise NotFound()
werkzeug.exceptions.NotFound: 404 Not Found: The requested URL was not found on the server. If you entered the URL manually please check your spelling and try again.

During handling of the above exception, another exception occurred:

Traceback (most recent call last):
  File "c:\code\personal\microblog\venv\lib\site-packages\flask\app.py", line 2070, in wsgi_app
    response = self.full_dispatch_request()
  File "c:\code\personal\microblog\venv\lib\site-packages\flask\app.py", line 1515, in full_dispatch_request
    rv = self.handle_user_exception(e)
  File "c:\code\personal\microblog\venv\lib\site-packages\flask\app.py", line 1383, in handle_user_exception
    return self.handle_http_exception(e)
  File "c:\code\personal\microblog\venv\lib\site-packages\flask\app.py", line 1323, in handle_http_exception
    return self.ensure_sync(handler)(e)
  File "C:\Code\Personal\microblog\app\errors.py", line 6, in not_found_error
    return render_template('404.html'), 404
  File "c:\code\personal\microblog\venv\lib\site-packages\flask\templating.py", line 147, in render_template
    return _render(
  File "c:\code\personal\microblog\venv\lib\site-packages\flask\templating.py", line 128, in _render
    rv = template.render(context)
  File "c:\code\personal\microblog\venv\lib\site-packages\jinja2\environment.py", line 1304, in render
    self.environment.handle_exception()
  File "c:\code\personal\microblog\venv\lib\site-packages\jinja2\environment.py", line 925, in handle_exception
    raise rewrite_traceback_stack(source=source)
  File "C:\Code\Personal\microblog\app\templates\404.html", line 1, in top-level template code
    {% extends "base.html" %}
  File "c:\code\personal\microblog\venv\lib\site-packages\jinja2\environment.py", line 925, in handle_exception
    raise rewrite_traceback_stack(source=source)
  File "C:\Code\Personal\microblog\app\templates\base.html", line 99, in template
    $(destElem).html('<img src="{{ url_for(\'static\', filename=\'loading.gif\') }}">');
jinja2.exceptions.TemplateSyntaxError: unexpected char '\\' at 3559
2021-09-09 21:44:47,279 INFO: Microblog startup [in C:\Code\Personal\microblog\app\__init__.py:52]
2021-09-09 21:46:19,728 INFO: Microblog startup [in C:\Code\Personal\microblog\app\__init__.py:52]
2021-09-09 21:51:35,230 INFO: Microblog startup [in C:\Code\Personal\microblog\app\__init__.py:52]
2021-09-09 21:53:41,786 INFO: Microblog startup [in C:\Code\Personal\microblog\app\__init__.py:52]
2021-09-09 22:00:49,499 INFO: Microblog startup [in C:\Code\Personal\microblog\app\__init__.py:52]
2021-09-09 22:01:09,699 INFO: Microblog startup [in C:\Code\Personal\microblog\app\__init__.py:52]
2021-09-09 22:04:09,745 INFO: Microblog startup [in C:\Code\Personal\microblog\app\__init__.py:52]
2021-09-09 22:06:36,842 INFO: Microblog startup [in C:\Code\Personal\microblog\app\__init__.py:52]
2021-09-09 22:09:02,400 INFO: Microblog startup [in C:\Code\Personal\microblog\app\__init__.py:52]
