2021-09-12 16:21:10,043 ERROR: Exception on /search [GET] [in c:\code\personal\microblog\venv\lib\site-packages\flask\app.py:1454]
Traceback (most recent call last):
  File "c:\code\personal\microblog\venv\lib\site-packages\urllib3\connection.py", line 169, in _new_conn
    conn = connection.create_connection(
  File "c:\code\personal\microblog\venv\lib\site-packages\urllib3\util\connection.py", line 96, in create_connection
    raise err
  File "c:\code\personal\microblog\venv\lib\site-packages\urllib3\util\connection.py", line 86, in create_connection
    sock.connect(sa)
ConnectionRefusedError: [WinError 10061] No connection could be made because the target machine actively refused it

During handling of the above exception, another exception occurred:

Traceback (most recent call last):
  File "c:\code\personal\microblog\venv\lib\site-packages\elasticsearch\connection\http_urllib3.py", line 251, in perform_request
    response = self.pool.urlopen(
  File "c:\code\personal\microblog\venv\lib\site-packages\urllib3\connectionpool.py", line 755, in urlopen
    retries = retries.increment(
  File "c:\code\personal\microblog\venv\lib\site-packages\urllib3\util\retry.py", line 507, in increment
    raise six.reraise(type(error), error, _stacktrace)
  File "c:\code\personal\microblog\venv\lib\site-packages\urllib3\packages\six.py", line 770, in reraise
    raise value
  File "c:\code\personal\microblog\venv\lib\site-packages\urllib3\connectionpool.py", line 699, in urlopen
    httplib_response = self._make_request(
  File "c:\code\personal\microblog\venv\lib\site-packages\urllib3\connectionpool.py", line 394, in _make_request
    conn.request(method, url, **httplib_request_kw)
  File "c:\code\personal\microblog\venv\lib\site-packages\urllib3\connection.py", line 234, in request
    super(HTTPConnection, self).request(method, url, body=body, headers=headers)
  File "C:\Users\xuse\AppData\Local\Programs\Python\Python39\lib\http\client.py", line 1257, in request
    self._send_request(method, url, body, headers, encode_chunked)
  File "C:\Users\xuse\AppData\Local\Programs\Python\Python39\lib\http\client.py", line 1303, in _send_request
    self.endheaders(body, encode_chunked=encode_chunked)
  File "C:\Users\xuse\AppData\Local\Programs\Python\Python39\lib\http\client.py", line 1252, in endheaders
    self._send_output(message_body, encode_chunked=encode_chunked)
  File "C:\Users\xuse\AppData\Local\Programs\Python\Python39\lib\http\client.py", line 1012, in _send_output
    self.send(msg)
  File "C:\Users\xuse\AppData\Local\Programs\Python\Python39\lib\http\client.py", line 952, in send
    self.connect()
  File "c:\code\personal\microblog\venv\lib\site-packages\urllib3\connection.py", line 200, in connect
    conn = self._new_conn()
  File "c:\code\personal\microblog\venv\lib\site-packages\urllib3\connection.py", line 181, in _new_conn
    raise NewConnectionError(
urllib3.exceptions.NewConnectionError: <urllib3.connection.HTTPConnection object at 0x0000025D43AF0A90>: Failed to establish a new connection: [WinError 10061] No connection could be made because the target machine actively refused it

During handling of the above exception, another exception occurred:

Traceback (most recent call last):
  File "c:\code\personal\microblog\venv\lib\site-packages\flask\app.py", line 2070, in wsgi_app
    response = self.full_dispatch_request()
  File "c:\code\personal\microblog\venv\lib\site-packages\flask\app.py", line 1515, in full_dispatch_request
    rv = self.handle_user_exception(e)
  File "c:\code\personal\microblog\venv\lib\site-packages\flask\app.py", line 1513, in full_dispatch_request
    rv = self.dispatch_request()
  File "c:\code\personal\microblog\venv\lib\site-packages\flask\app.py", line 1499, in dispatch_request
    return self.ensure_sync(self.view_functions[rule.endpoint])(**req.view_args)
  File "c:\code\personal\microblog\venv\lib\site-packages\flask_login\utils.py", line 272, in decorated_view
    return func(*args, **kwargs)
  File "C:\Code\Personal\microblog\app\main\routes.py", line 159, in search
    posts, total = Post.search(g.search_form.q.data, page,
  File "C:\Code\Personal\microblog\app\models.py", line 88, in search
    ids, total = query_index(cls.__tablename__, expression, page, per_page)
  File "C:\Code\Personal\microblog\app\search.py", line 20, in query_index
    search = current_app.elasticsearch.search(
  File "c:\code\personal\microblog\venv\lib\site-packages\elasticsearch\client\utils.py", line 168, in _wrapped
    return func(*args, params=params, headers=headers, **kwargs)
  File "c:\code\personal\microblog\venv\lib\site-packages\elasticsearch\client\__init__.py", line 1668, in search
    return self.transport.perform_request(
  File "c:\code\personal\microblog\venv\lib\site-packages\elasticsearch\transport.py", line 409, in perform_request
    self._do_verify_elasticsearch(headers=headers, timeout=timeout)
  File "c:\code\personal\microblog\venv\lib\site-packages\elasticsearch\transport.py", line 598, in _do_verify_elasticsearch
    raise error
  File "c:\code\personal\microblog\venv\lib\site-packages\elasticsearch\transport.py", line 561, in _do_verify_elasticsearch
    _, info_headers, info_response = conn.perform_request(
  File "c:\code\personal\microblog\venv\lib\site-packages\elasticsearch\connection\http_urllib3.py", line 266, in perform_request
    raise ConnectionError("N/A", str(e), e)
elasticsearch.exceptions.ConnectionError: ConnectionError(<urllib3.connection.HTTPConnection object at 0x0000025D43AF0A90>: Failed to establish a new connection: [WinError 10061] No connection could be made because the target machine actively refused it) caused by: NewConnectionError(<urllib3.connection.HTTPConnection object at 0x0000025D43AF0A90>: Failed to establish a new connection: [WinError 10061] No connection could be made because the target machine actively refused it)
2021-09-12 16:36:35,423 INFO: Microblog startup [in C:\Code\Personal\microblog\app\__init__.py:77]
2021-09-12 16:36:48,146 ERROR: Exception on /search [GET] [in c:\code\personal\microblog\venv\lib\site-packages\flask\app.py:1454]
Traceback (most recent call last):
  File "c:\code\personal\microblog\venv\lib\site-packages\flask\app.py", line 2070, in wsgi_app
    response = self.full_dispatch_request()
  File "c:\code\personal\microblog\venv\lib\site-packages\flask\app.py", line 1515, in full_dispatch_request
    rv = self.handle_user_exception(e)
  File "c:\code\personal\microblog\venv\lib\site-packages\flask\app.py", line 1513, in full_dispatch_request
    rv = self.dispatch_request()
  File "c:\code\personal\microblog\venv\lib\site-packages\flask\app.py", line 1499, in dispatch_request
    return self.ensure_sync(self.view_functions[rule.endpoint])(**req.view_args)
  File "c:\code\personal\microblog\venv\lib\site-packages\flask_login\utils.py", line 272, in decorated_view
    return func(*args, **kwargs)
  File "C:\Code\Personal\microblog\app\main\routes.py", line 159, in search
    posts, total = Post.search(g.search_form.q.data, page,
  File "C:\Code\Personal\microblog\app\models.py", line 88, in search
    ids, total = query_index(cls.__tablename__, expression, page, per_page)
  File "C:\Code\Personal\microblog\app\search.py", line 20, in query_index
    search = current_app.elasticsearch.search(
  File "c:\code\personal\microblog\venv\lib\site-packages\elasticsearch\client\utils.py", line 168, in _wrapped
    return func(*args, params=params, headers=headers, **kwargs)
  File "c:\code\personal\microblog\venv\lib\site-packages\elasticsearch\client\__init__.py", line 1668, in search
    return self.transport.perform_request(
  File "c:\code\personal\microblog\venv\lib\site-packages\elasticsearch\transport.py", line 458, in perform_request
    raise e
  File "c:\code\personal\microblog\venv\lib\site-packages\elasticsearch\transport.py", line 419, in perform_request
    status, headers_response, data = connection.perform_request(
  File "c:\code\personal\microblog\venv\lib\site-packages\elasticsearch\connection\http_urllib3.py", line 277, in perform_request
    self._raise_error(response.status, raw_data)
  File "c:\code\personal\microblog\venv\lib\site-packages\elasticsearch\connection\base.py", line 330, in _raise_error
    raise HTTP_EXCEPTIONS.get(status_code, TransportError)(
elasticsearch.exceptions.NotFoundError: NotFoundError(404, 'index_not_found_exception', 'no such index [post]', post, index_or_alias)
2021-09-12 16:38:09,061 INFO: Microblog startup [in C:\Code\Personal\microblog\app\__init__.py:77]
