2020-12-10 15:02:54,088 ERROR: Exception on /login [GET] [in c:\users\xuse\appdata\local\programs\python\python39\lib\site-packages\flask\app.py:1891]
Traceback (most recent call last):
  File "c:\users\xuse\appdata\local\programs\python\python39\lib\site-packages\flask\app.py", line 2447, in wsgi_app
    response = self.full_dispatch_request()
  File "c:\users\xuse\appdata\local\programs\python\python39\lib\site-packages\flask\app.py", line 1952, in full_dispatch_request
    rv = self.handle_user_exception(e)
  File "c:\users\xuse\appdata\local\programs\python\python39\lib\site-packages\flask\app.py", line 1821, in handle_user_exception
    reraise(exc_type, exc_value, tb)
  File "c:\users\xuse\appdata\local\programs\python\python39\lib\site-packages\flask\_compat.py", line 39, in reraise
    raise value
  File "c:\users\xuse\appdata\local\programs\python\python39\lib\site-packages\flask\app.py", line 1950, in full_dispatch_request
    rv = self.dispatch_request()
  File "c:\users\xuse\appdata\local\programs\python\python39\lib\site-packages\flask\app.py", line 1936, in dispatch_request
    return self.view_functions[rule.endpoint](**req.view_args)
  File "C:\Code\Personal\microblog\app\routes.py", line 29, in login
    return render_template('login.html', title='Sign In', form=form)
  File "c:\users\xuse\appdata\local\programs\python\python39\lib\site-packages\flask\templating.py", line 137, in render_template
    return _render(
  File "c:\users\xuse\appdata\local\programs\python\python39\lib\site-packages\flask\templating.py", line 120, in _render
    rv = template.render(context)
  File "c:\users\xuse\appdata\local\programs\python\python39\lib\site-packages\jinja2\environment.py", line 1090, in render
    self.environment.handle_exception()
  File "c:\users\xuse\appdata\local\programs\python\python39\lib\site-packages\jinja2\environment.py", line 832, in handle_exception
    reraise(*rewrite_traceback_stack(source=source))
  File "c:\users\xuse\appdata\local\programs\python\python39\lib\site-packages\jinja2\_compat.py", line 28, in reraise
    raise value.with_traceback(tb)
  File "C:\Code\Personal\microblog\app\templates\login.html", line 1, in top-level template code
    {% extends 'base.html' %}
  File "c:\users\xuse\appdata\local\programs\python\python39\lib\site-packages\jinja2\environment.py", line 832, in handle_exception
    reraise(*rewrite_traceback_stack(source=source))
  File "c:\users\xuse\appdata\local\programs\python\python39\lib\site-packages\jinja2\_compat.py", line 28, in reraise
    raise value.with_traceback(tb)
  File "C:\Code\Personal\microblog\app\templates\base.html", line 57, in template
    {% block content %}{% endblock %}
jinja2.exceptions.TemplateAssertionError: block 'content' defined twice
2020-12-10 15:02:55,835 ERROR: Exception on /favicon.ico [GET] [in c:\users\xuse\appdata\local\programs\python\python39\lib\site-packages\flask\app.py:1891]
Traceback (most recent call last):
  File "c:\users\xuse\appdata\local\programs\python\python39\lib\site-packages\flask\app.py", line 1950, in full_dispatch_request
    rv = self.dispatch_request()
  File "c:\users\xuse\appdata\local\programs\python\python39\lib\site-packages\flask\app.py", line 1926, in dispatch_request
    self.raise_routing_exception(req)
  File "c:\users\xuse\appdata\local\programs\python\python39\lib\site-packages\flask\app.py", line 1908, in raise_routing_exception
    raise request.routing_exception
  File "c:\users\xuse\appdata\local\programs\python\python39\lib\site-packages\flask\ctx.py", line 350, in match_request
    result = self.url_adapter.match(return_rule=True)
  File "c:\users\xuse\appdata\local\programs\python\python39\lib\site-packages\werkzeug\routing.py", line 1945, in match
    raise NotFound()
werkzeug.exceptions.NotFound: 404 Not Found: The requested URL was not found on the server. If you entered the URL manually please check your spelling and try again.

During handling of the above exception, another exception occurred:

Traceback (most recent call last):
  File "c:\users\xuse\appdata\local\programs\python\python39\lib\site-packages\flask\app.py", line 2447, in wsgi_app
    response = self.full_dispatch_request()
  File "c:\users\xuse\appdata\local\programs\python\python39\lib\site-packages\flask\app.py", line 1952, in full_dispatch_request
    rv = self.handle_user_exception(e)
  File "c:\users\xuse\appdata\local\programs\python\python39\lib\site-packages\flask\app.py", line 1816, in handle_user_exception
    return self.handle_http_exception(e)
  File "c:\users\xuse\appdata\local\programs\python\python39\lib\site-packages\flask\app.py", line 1744, in handle_http_exception
    return handler(e)
  File "C:\Code\Personal\microblog\app\errors.py", line 6, in not_found_error
    return render_template('404.html'), 404
  File "c:\users\xuse\appdata\local\programs\python\python39\lib\site-packages\flask\templating.py", line 137, in render_template
    return _render(
  File "c:\users\xuse\appdata\local\programs\python\python39\lib\site-packages\flask\templating.py", line 120, in _render
    rv = template.render(context)
  File "c:\users\xuse\appdata\local\programs\python\python39\lib\site-packages\jinja2\environment.py", line 1090, in render
    self.environment.handle_exception()
  File "c:\users\xuse\appdata\local\programs\python\python39\lib\site-packages\jinja2\environment.py", line 832, in handle_exception
    reraise(*rewrite_traceback_stack(source=source))
  File "c:\users\xuse\appdata\local\programs\python\python39\lib\site-packages\jinja2\_compat.py", line 28, in reraise
    raise value.with_traceback(tb)
  File "C:\Code\Personal\microblog\app\templates\404.html", line 1, in top-level template code
    {% extends 'base.html' %}
  File "c:\users\xuse\appdata\local\programs\python\python39\lib\site-packages\jinja2\environment.py", line 832, in handle_exception
    reraise(*rewrite_traceback_stack(source=source))
  File "c:\users\xuse\appdata\local\programs\python\python39\lib\site-packages\jinja2\_compat.py", line 28, in reraise
    raise value.with_traceback(tb)
  File "C:\Code\Personal\microblog\app\templates\base.html", line 57, in template
    {% block content %}{% endblock %}
jinja2.exceptions.TemplateAssertionError: block 'content' defined twice
2020-12-10 15:04:34,695 INFO: Microblog startup [in C:\Code\Personal\microblog\app\__init__.py:49]
2020-12-10 15:04:42,348 ERROR: Exception on /login [GET] [in c:\users\xuse\appdata\local\programs\python\python39\lib\site-packages\flask\app.py:1891]
Traceback (most recent call last):
  File "c:\users\xuse\appdata\local\programs\python\python39\lib\site-packages\flask\app.py", line 2447, in wsgi_app
    response = self.full_dispatch_request()
  File "c:\users\xuse\appdata\local\programs\python\python39\lib\site-packages\flask\app.py", line 1952, in full_dispatch_request
    rv = self.handle_user_exception(e)
  File "c:\users\xuse\appdata\local\programs\python\python39\lib\site-packages\flask\app.py", line 1821, in handle_user_exception
    reraise(exc_type, exc_value, tb)
  File "c:\users\xuse\appdata\local\programs\python\python39\lib\site-packages\flask\_compat.py", line 39, in reraise
    raise value
  File "c:\users\xuse\appdata\local\programs\python\python39\lib\site-packages\flask\app.py", line 1950, in full_dispatch_request
    rv = self.dispatch_request()
  File "c:\users\xuse\appdata\local\programs\python\python39\lib\site-packages\flask\app.py", line 1936, in dispatch_request
    return self.view_functions[rule.endpoint](**req.view_args)
  File "C:\Code\Personal\microblog\app\routes.py", line 29, in login
    return render_template('login.html', title='Sign In', form=form)
  File "c:\users\xuse\appdata\local\programs\python\python39\lib\site-packages\flask\templating.py", line 137, in render_template
    return _render(
  File "c:\users\xuse\appdata\local\programs\python\python39\lib\site-packages\flask\templating.py", line 120, in _render
    rv = template.render(context)
  File "c:\users\xuse\appdata\local\programs\python\python39\lib\site-packages\jinja2\environment.py", line 1090, in render
    self.environment.handle_exception()
  File "c:\users\xuse\appdata\local\programs\python\python39\lib\site-packages\jinja2\environment.py", line 832, in handle_exception
    reraise(*rewrite_traceback_stack(source=source))
  File "c:\users\xuse\appdata\local\programs\python\python39\lib\site-packages\jinja2\_compat.py", line 28, in reraise
    raise value.with_traceback(tb)
  File "C:\Code\Personal\microblog\app\templates\login.html", line 1, in top-level template code
    {% extends 'base.html' %}
  File "c:\users\xuse\appdata\local\programs\python\python39\lib\site-packages\jinja2\environment.py", line 832, in handle_exception
    reraise(*rewrite_traceback_stack(source=source))
  File "c:\users\xuse\appdata\local\programs\python\python39\lib\site-packages\jinja2\_compat.py", line 28, in reraise
    raise value.with_traceback(tb)
  File "C:\Code\Personal\microblog\app\templates\base.html", line 81, in template
    {% block content %}{% endblock %}
jinja2.exceptions.TemplateAssertionError: block 'content' defined twice
2020-12-10 15:05:18,323 INFO: Microblog startup [in C:\Code\Personal\microblog\app\__init__.py:49]
2020-12-10 15:14:32,744 INFO: Microblog startup [in C:\Code\Personal\microblog\app\__init__.py:49]
2020-12-10 15:23:55,604 INFO: Microblog startup [in C:\Code\Personal\microblog\app\__init__.py:49]
2020-12-10 15:25:54,288 INFO: Microblog startup [in C:\Code\Personal\microblog\app\__init__.py:49]
2020-12-10 15:26:16,242 INFO: Microblog startup [in C:\Code\Personal\microblog\app\__init__.py:49]
2020-12-10 15:29:26,692 INFO: Microblog startup [in C:\Code\Personal\microblog\app\__init__.py:49]
2020-12-10 15:29:48,860 INFO: Microblog startup [in C:\Code\Personal\microblog\app\__init__.py:49]
2020-12-10 15:30:19,262 INFO: Microblog startup [in C:\Code\Personal\microblog\app\__init__.py:49]
2020-12-10 15:35:38,452 INFO: Microblog startup [in C:\Code\Personal\microblog\app\__init__.py:49]
